<?xml version="1.0" ?>
<robot xmlns:xacro="http://www.ros.org/wiki/xacro">

<xacro:macro
	name="roller_macro"
	params="parent name xyz rpy">

		<link name="roller_${name}_rim_${parent}_link">
			<inertial>
				<mass value="0.001107675"/>
				<!-- 0.00113845 -->
				<!-- 0.001707675 -->
				<inertia
				ixx="10.53776e-08"
				ixy="0"
				ixz="0"
				iyy="10.53776e-08"
				iyz="0"
				izz="10.47666e-08"/>
			</inertial>
			<visual>
				<geometry>
					<mesh filename="package://swarm_simulation/models/wheel/meshes/roller.stl" scale = "1.5 1.5 1.5"/>
				</geometry>
				<material name="roller_material">
					<color rgba="0.1 0.1 0.1 1"/>
				</material>
			</visual>
			<collision>
				<geometry>
					<mesh filename="package://swarm_simulation/models/wheel/meshes/roller.stl" scale = "1.5 1.5 1.5"/>
				</geometry>
			</collision>
		</link>
	<gazebo reference="roller_${name}_rim_${parent}_link">
    		<material>Gazebo/Black</material>
  	</gazebo>
		<joint name="roller_${name}_rim_${parent}_joint" type="continuous">
			<parent link="rim_${parent}_link"/>
			<child link="roller_${name}_rim_${parent}_link"/>
			<axis xyz="0 0 1"/>
			<origin xyz="${xyz}" rpy="${rpy}"/>
			<!-- <dynamics damping = "1.0" friction = "1.0" /> -->
		</joint>
	</xacro:macro>

</robot>



<!-- ixx="2.53776e-08"
ixy="0"
ixz="0"
iyy="2.53776e-08"
iyz="0"
izz="1.47666e-08" -->


<!-- Scale 1.5 -->
<!-- ixx = "3.80664e-08"
ixy="0"
ixz="0"
iyy="3.80664e-08"
iyz="0"
izz="2.21499e-08" -->